Workbook

Sheet Offer Overview
A1: AI SDLC — Oferta wdrożenia
A3: Executive Summary
A4: Bottega proponuje kompleksowe wdrożenie inżynierii oprogramowania wspomaganej sztuczną inteligencją (AI SDLC) w dwóch obszarach biznesowych: Bankowość Centralna oraz Capital Markets, wraz z opcjonalną technologiczną restrukturyzacją wybranych modułów. Oferta obejmuje budowę baz wiedzy i dokumentacji zoptymalizowanej pod AI, konfigurację narzędzi i instrukcji dla analityków, developerów i reviewerów, wdrożenie automatyzacji CI/CD oraz security gates, a także szkolenia i transfer know-how. Łączna wartość inwestycji: =SUM(E11,E19,E27,E35,E43,E51) PLN netto.
A6: Podejście i fazy wdrożenia
A7: Nasze podejście to stopniowa ewolucja, a nie rewolucja. Integrujemy AI tam, gdzie przynosi wymierny zwrot z inwestycji i odciąża inżynierów od powtarzalnych zadań, unikając pułapek związanych z bezpieczeństwem, halucynacjami modeli i obniżeniem jakości kodu.
A8: Faza 1 — Audit i strategia | B8: Analiza procesu wytwórczego, stosu technologicznego i kultury inżynierskiej. Identyfikacja obszarów o najwyższym potencjale zwrotu. Wynik: roadmapa wdrożenia.
A9: Faza 2 — Proof of Value | B9: Pilotaż na wybranym zespole lub module. Praca własna Bottega (przygotowanie narzędzi, dokumentacji) + pair programming online (transfer know-how). Wynik: działające rozwiązanie + udowodniona wartość przed skalowaniem.
A10: Faza 3 — Skalowanie kompetencji | B10: Rozszerzenie praktyk na całą organizację. Przekazanie licencji z bezterminowym prawem do użytku. Szkolenia dla analityków, PM i developerów.
A12: Zakres wdrożenia
A13: TOTAL.01 — Bankowość Centralna — AI SDLC | B13: Pełen zestaw praktyk AI SDLC: skonsolidowanie dokumentacji funkcji systemu (IK.1), mapowanie funkcjonalności na kod i architekturę (IK.2), dokumentacja frontendu i backendu dla AI (IK.4, IK.5), instrukcje AI do analizy regulatorów KNF/UE (EK.1), narzędzia dla analityków i developerów (TL.1–TL.5). Efekt: wspólny język z AI, szybsza analiza impaktu, eliminacja błędów z nieaktualnej dokumentacji. | E13: ='Central Banking'!H282
A14: TOTAL.02 — Capital Markets — AI SDLC | B14: Analogiczny zakres jak TOTAL.01, dostosowany do specyfiki Capital Markets (regulator GPW). Większy wymiar pracy własnej Bottega by odciążyć zespół klienta. | E14: ='Capital Markets'!H281
A15: TOTAL.03 — Capital Markets — Refaktoryzacja | B15: Standaryzacja CI/CD (Jenkinsfile, shared library), migracja Ant→Maven/Gradle, automatyzacja deploy QA, ujednolicenie artefaktów, iOS build/release (Fastlane), security gates (Fortify, Dependency-Track), plan migracji z wyceną etapową. | E15: ='Refactor Capital Markets'!H143
A16: TOTAL.04 — Pakiet szkoleń | B16: Szkolenie AI SDLC dla analityków i PM (2 dni) oraz dla developerów (3 dni). Bazuje na realnych zadaniach i kodzie projektów. | E16: =SUM(Podsumowanie!E31:E34)
A17: TOTAL.05 — Gwarancja 1 rok / Bufor | B17: Pakiet dodatkowych godzin na bieżące wsparcie, korekty i niespodziewane wyzwania po wdrożeniu. | E17: =SUM(Podsumowanie!E39:E42)
A18: TOTAL.06 — Narzędzia i licencje | B18: Przekazanie licencji na narzędzia AI SDLC z bezterminowymi prawami do wewnętrznego użytku i własnego rozwoju. | E18: =Narzędzia!G86
A19: Łączna wartość | E19: =SUM(Podsumowanie!E11,Podsumowanie!E19,Podsumowanie!E27,Podsumowanie!E35,Podsumowanie!E43,Podsumowanie!E51)
A21: Efekty biznesowe
A22: Przyspieszenie Time-to-Market | B22: Automatyzacja powtarzalnych zadań skraca czas dostarczania funkcjonalności. AI przejmuje żmudne czynności, inżynierowie skupiają się na pracy twórczej. → TOTAL.01, TOTAL.02, TOTAL.03
A23: Redukcja długu technicznego | B23: Systematyczna poprawa jakości kodu i architektury przez AI Review (bugs, architektura, complexicity, zgodność ze specyfikacją). → TOTAL.03, TOTAL.01, TOTAL.02
A24: Retencja wiedzy projektowej | B24: AI jako "kustosz wiedzy" — skonsolidowana dokumentacja, baza wiedzy mapująca funkcjonalność na kod. Szybsze wdrażanie nowych pracowników, minimalizacja ryzyka utraty wiedzy przy rotacji. → TOTAL.01, TOTAL.02, TOTAL.06
A25: Skalowanie kompetencji | B25: Ujednolicenie standardów pracy. Dzięki narzędziom i instrukcjom AI każdy inżynier pracuje według tych samych wzorców. → TOTAL.04, TOTAL.01, TOTAL.02
A26: Bezpieczeństwo danych | B26: Pełna kontrola nad kodem źródłowym i dokumentacją. Gating bezpieczeństwa w pipeline. Opcje: Cloud Native, Private Cloud (VPC) lub On-Premise (Air-Gapped). → TOTAL.03, TOTAL.06
A28: Model dostawy
A29: Forma współpracy | B29: Opis | C29: Kiedy stosujemy
A30: Praca własna Bottega | B30: Eksperci Bottega realizują zadania samodzielnie, bez angażowania zespołu klienta | C30: Budowa narzędzi, dokumentacji, instrukcji
A31: Pair programming online | B31: Wspólna praca eksperta Bottega z inżynierem klienta w parach, przekazująca know-how w czasie rzeczywistym | C31: Transfer kompetencji: context engineering, refactoring, pipeline
A32: Review po stronie klienta | B32: Klient weryfikuje efekty prac Bottega, otrzymuje feedback i możliwość korekty | C32: Każda dostarczona pozycja przed zamknięciem
A33: Środowiska docelowe
B34: Cloud Native (Enterprise API) — dla firm akceptujących przetwarzanie w chmurze z umowami BAA, stawiających na najwyższą inteligencję modeli
B35: Private Cloud (VPC) — dla organizacji wymagających zgodności z regulacjami korporacyjnymi, posiadających infrastrukturę w chmurze publicznej
B36: On-Premise (Air-Gapped) — dla banków i sektora publicznego o najwyższym rygorze tajności; obejmuje dobór hardware'u, konfigurację i support
A38: Ryzyka i mitigacje
A39: Ryzyko | B39: Mitigacja
A40: Halucynacje modeli AI — AI generuje nieprawdziwe lub niepoprawne informacje | B40: Context engineering — budowa precyzyjnego kontekstu dla LLM; instrukcje AI wymuszające weryfikację faktów; rola człowieka w pętli (human-in-the-loop)
A41: Obniżenie jakości kodu — AI generuje kod niezgodny ze standardami | B41: AI Review w pipeline (bugs, architektura, complexicity, zgodność ze specyfikacją); gating security (Fortify, Dependency-Track); code review przez doświadczonych inżynierów
A42: Wyciek danych / kodu źródłowego — wrażliwy kod trafia do publicznych modeli AI | B42: Możliwość deploymentu On-Premise (Air-Gapped); Private Cloud (VPC); polityka danych i instrukcje AI wymuszające lokalne przetwarzanie
A43: Odrzucenie przez zespół — inżynierowie nie chcą pracować z AI | B43: Stopniowe wprowadzanie (ewolucja, nie rewolucja); pokazanie wartości na pilocie; szkolenia i mentoring; odciążenie od powtarzalnych zadań
A44: Ponoszenie zbędnych kosztów — niewłaściwe użycie AI przez nieprzeszkolony personel | B44: Harness engineering — znacząco podnosi jakość przy wykorzystaniu mniejszych modeli; oszczędności dzięki wycinaniu zbędnego outputu i logów; szkolenia z efektywnego korzystania z AI (TOTAL.04)
A45: Uzależnienie od dostawcy (vendor lock-in) | B45: Przekazanie narzędzi i licencji na własność; bezterminowe prawa do wewnętrznego użytku i rozwoju; transfer know-how przez pair programming; dokumentacja i instrukcje pozostają w organizacji
A47: Dlaczego Bottega
...

Sheet Podsumowanie
A1: Podsumowanie
A4: Kod | B4: Obszar | C4: Tytul / opis | D4: Pozycja kosztowa | E4: Cena netto [PLN] | F4: Typ do podsumowania | G4: Opis oferty
A5: TOTAL.01 | B5: Bankowość | C5: Wdrożenie AI SDLC z przekazaniem Know-How dla BU Bankowość | G5: TOTAL.01 — Bankowość Centralna: AI SDLC + Know-How Pełen zestaw praktyk AI SDLC: skonsolidowanie dokumentacji funkcji systemu (IK.1), mapowanie funkcjonalności na kod i architekturę (IK.2), dokumentacja frontendu i backendu zoptymalizowana pod AI (IK.4, IK.5), instrukcje AI do analizy regulatorów KNF/UE (EK.1) oraz narzędzia i instrukcje dla analityków i developerów (TL.1–TL.5).
C6: Wdrożenie AI SDLC w formie pair programming (online) z przekazaniem knowhow dotyczącym wdrażania AI SDLC. | D6: Opis
D7: Przekazanie knowhow | E7: ='Central Banking'!H284 | F7: knowhow
D8: Wykonanie AI SDLC | E8: ='Central Banking'!H285 | F8: AI SDLC
D11: Suma | E11: ='Central Banking'!H282
A13: TOTAL.02 | B13: Capital Markets | C13: Wdrożenie AI SDLC z przekazaniem Know-How dla BU Capital Markets | G13: TOTAL.02 — Capital Markets: AI SDLC + Know-How Analogiczny zakres jak dla Bankowości Centralnej, dostosowany do specyfiki BU Capital Markets (w tym regulator GPW). Większy wymiar pracy własnej Bottega by odciążyć zespół klienta.
C14: Wdrożenie AI SDLC w formie: - praca własna po stronie Bottega by ograniczyć prace po - pair programming (online) by przekazać knowhow dotyczącym wdrażania AI SDLC | D14: Opis
D15: Przekazanie knowhow | E15: ='Capital Markets'!H283 | F15: knowhow
D16: Wykonanie AI SDLC | E16: ='Capital Markets'!H284 | F16: AI SDLC
D19: Suma | E19: ='Capital Markets'!H281
A21: TOTAL.03 | B21: Capital Markets | C21: Technologiczna restrykturyzacja | G21: TOTAL.03 — Capital Markets: Technologiczna restrukturyzacja Standaryzacja CI/CD na Jenkinsfile (REF.1), migracja builda Ant→Maven/Gradle (REF.2), automatyzacja deploy QA (REF.3), ujednolicenie artefaktów (REF.4), iOS build/release przez Fastlane (REF.5), Fortify/Dependency-Track z gatingiem (REF.6), plan migracji z wyceną etapową (REF.RE.1).
C22: Wprowadzenie technologicznych zmian w projekt w formie: - pracy własnej po stronie Bottega - oraz pair programming (online) w ramach potrzeb i dostępności. | D22: Opis
D23: Przekazanie narzedzi | E23: ='Refactor Capital Markets'!H144 | F23: narzedzia
D24: Przekazanie knowhow | E24: ='Refactor Capital Markets'!H145 | F24: knowhow
D25: Wykonanie prac | E25: ='Refactor Capital Markets'!H146 | F25: refactor
D27: Suma | E27: ='Refactor Capital Markets'!H143
A29: TOTAL.04 | C29: Pakiet szkoleń | G29: TOTAL.04 — Pakiet szkoleń Szkolenia dla szerszego grona pracowników: AI SDLC dla analityków i PM (2 dni) oraz dla developerów (3 dni). Bazują na realnych zadaniach i kodzie projektów.
C30: Szkolenia dla szerszego grona pracowników, jak efektywnie pracować z AI SDLC wdrożonym do projektów. Szkolenia mogą bazować na realnych zadaniach i kodzie projektów, jeśli będzie to dopuszczalne. | D30: Opis
D31: Szkolenie AI SDLC dla analityków i PM 2dni | E31: 10000 | F31: szkolenia
D32: Szkolenie AI SDLC dla developerów 3dni | E32: 15000 | F32: szkolenia
D35: Suma | E35: =SUM(E31:E34)
A37: TOTAL.05 | C37: Gwarancja 1 rok / bufor dodatkowych godzin | G37: TOTAL.05 — Gwarancja 1 rok / Bufor Pakiet dodatkowych godzin na bieżące wsparcie, korekty i niespodziewane wyzwania po wdrożeniu.
C38: Pakiet dodatkowych godzin prac zarówno nad AI SDLC jak i technologiczną restrukturyzacją. | D38: Opis
D39: Bufor i Gwarancja | E39: 25000 | F39: inne
D43: Suma | E43: =SUM(E39:E42)
A45: TOTAL.06 | C45: Przekazanie narzędzi AI SDLC i licencji | G45: TOTAL.06 — Przekazanie narzędzi i licencji Licencje na narzędzia AI SDLC z bezterminowymi prawami do wewnętrznego użytku i własnego rozwoju.
C46: Przekazanie licencji na narzędzia dla AI SDLC, bezterminowe prawa do wewnętrznego użycia i własnego rozwoju. | D46: Przekazanie Rekomendacji | E46: =Narzędzia!H89 | F46: knowhow
D47: Przekazanie narzedzi | E47: =Narzędzia!H88 | F47: narzedzia
D51: Suma | E51: =Narzędzia!G86
D56: Całkowita Suma | E56: =SUM(E11,E19,E27,E35,E43,E51)

Sheet Central Banking
A1: AI SDLC z przekazaniem Know-How
A2: BU: | B2: Bankowść Centralna
A4: Kod | B4: Obszar | C4: Tytul / opis | D4: Pozycja kosztowa | F4: Typ do podsumowania | G4: Cena netto [PLN] | H4: Suma | I4: Value proposition
A7: IK.1 | B7: IK (Internal Knowledge) | C7: IK.1 - Skonsolidowana dokumentacja funkcji systemu (aktualnych wersji) dla AI | D7: Sekcja | I7: Analityk: pewność że AI rozumie aktualny stan systemu. Developer: AI i agenci wiedzą co jest już zaimplementowane. Reviewer: kontekst do oceny impaktu. QA: pełny kontekst systemu.
C8: Analiza: Analitycy zyskują pewność, że AI rozumie aktualny stan systemu i impakt na istniejącą funkcjonalność. Skraca to czas weryfikacji pomysłów i redukuje błędy wynikające z nieaktualnej wiedzy. Development: Developerzy i agenci wiedzą co jest już zaimplementowane i AI pomoże im to odszukać. Review: Reviewerzy mają kontekst do oceny czy zmiana nie koliduje z istniejącą funkcjonalnością, jaki jest impakt przed implementacją, czy implementacja została zrealizowana. Testing: QA rozumie pełny kontekst systemu i wie co należy przetestować po zmianach proponowanych w analizie. | D8: Opis
D9: Przekazanie knowhow | F9: knowhow | G9: 2500
D10: Wykonanie skonsolidowanej dokumentacji funkcji systemu (jednej wersji) dla AI | F10: AI SDLC | G10: 7500
D11: Review prac po stronie | F11: AI SDLC | G11: 500
D12: Suma IK.1 | H12: =SUM(G9:G11)
A14: IK.2 | B14: IK (Internal Knowledge) | C14: IK.2 - Baza wiedzy mapująca funkcjonalność na kod / architekturę (funkcjonalność -> UI -> Beans -> baza danych) | D14: Sekcja | I14: Analityk: AI wskazuje miejsca zmian po opisie. Developer: wie dokładnie gdzie zmieniać kod. Reviewer: ocenia pełen impact. QA: wie co testować.
C15: Analiza: Po napisaniu opisu zmian AI wskazuje potencjalne miejsca zmian w kodzie i dokumentacji, a analityk robi finalną walidację. Automatyczne mapowanie nazewnictwa PL (analiza) vs EN (kod) ogranicza błędy wynikające z dwóch języków. Development: Developerzy wiedzą dokładnie gdzie i jak zmieniać kod. Review: Reviewerzy mogą ocenić pełen impact zmiany na kod i architekturę. Testing: Testerzy wiedzą co musi być przetestowane po zmianie. | D15: Opis
D16: Przekazanie knowhow | F16: knowhow | G16: 2500
D17: Wykonanie bazy wiedzy mapującej funkcjonalność na kod i architekturę | F17: AI SDLC | G17: 3750
D18: Review prac po stronie | F18: AI SDLC | G18: 500
D19: Suma IK.2 | H19: =SUM(G16:G18)
A21: IK.3 | B21: IK (Internal Knowledge) | C21: IK.3 - Heurystyczne szacowanie pracochłonności (w oparciu o wartości eksperckie) | D21: Sekcja | I21: Liderzy: estymaty oparte na wartościach eksperckich.
C22: opcja A. (zalecana) szacowanie z wartościami eksperckimi opcja B. (odradzamy) liczenie metryk na bazie kodu/jira jeśli nie istnieją Analiza: Porównujemy artefakty analityczne z realnym stanem systemu, by estymować postęp i złożoność zmian. Liderzy projektu zyskują estymaty oparte na wartościach eksperckich. | D22: Opis
D23: Przekazanie knowhow | F23: knowhow | G23: 0
D24: Przygotowanie heurystycznego szacowania pracochłonności | F24: AI SDLC | G24: 700
D25: Review prac po stronie | F25: AI SDLC | G25: 0
D26: Suma IK.3 | H26: =SUM(G23:G25)
A28: IK.4 | B28: IK (Internal Knowledge) | C28: IK.4 - Skonsolidowana dokumentacja architektury frontendu optymalna dla AI | D28: Sekcja | I28: Analityk: szybsza ocena impaktu na frontend. Developer: AI generuje kod zgodny z architekturą. Reviewer: zgodność z zasadami. QA: spójne testy UI.
C29: Analiza: Ocena impakty zmian na frontendzie. Development: AI generuje kod zgodny z lokalną architekturą i wzorcami. AI i developerzy mają jasne wzorce jak pisać frontend - formularze, tabelki, nazewnictwo, elementy common. Dodatkowe instrukcja uświadamiające AI odnośnie hacków primefaces. Review: Reviewerzy sprawdzają zgodność z zasadami architektonicznymi frontendu. Testing: UI testy e2e są spójne i zgodne z wzorcami. | D29: Opis
D30: Przekazanie knowhow | F30: knowhow | G30: 1250
D31: Wykonanie skonsolidowanej dokumentacji architektury frontendu dla AI | F31: AI SDLC | G31: 1250
D32: Review prac po stronie | F32: AI SDLC | G32: 1250
D33: Suma IK.4 | H33: =SUM(G30:G32)
A35: IK.5 | B35: IK (Internal Knowledge) | C35: IK.5 - Skonsolidowana dokumentacja architektury backendu optymalna dla AI | D35: Sekcja | I35: Analityk: szybsza ocena impaktu na backend. Developer: AI generuje kod zgodny z wzorcami backendu. Reviewer: zgodność architektoniczna. QA: testy zgodne ze wzorcami.
C36: Analiza: Ocena impakty zmian na backendzie. Development: AI generuje kod zgodny z lokalną architekturą i wzorcami. AI i developerzy mają jasne wzorce jak pisać backend - Beana, encje, procedury składowane i exception handling. Review: Reviewerzy sprawdzają zgodność z zasadami architektonicznymi backendu. Testing: Testy backendowe są spójne z przyjętymi wzorcami. AI rozumie strukturę i może pisać testy jednostkowe i integracyjne zgodne z wzorcami. | D36: Opis
D37: Przekazanie knowhow | F37: knowhow | G37: 1250
D38: Wykonanie skonsolidowanej dokumentacji architektury backendu dla AI | F38: AI SDLC | G38: 1250
D39: Review prac po stronie | F39: AI SDLC | G39: 1250
D40: Suma IK.5 | H40: =SUM(G37:G39)
A42: IK.7 | B42: IK (Internal Knowledge) | C42: IK.7 - Implementacja obecnie brakujących scenariuszy e2e (pracochłonne dla wszystkich) | D42: Sekcja | I42: Analityk: brakujące scenariusze z AI. Developer: scenariusze z danymi. Reviewer: sprawdza pokrycie. QA: gotowe e2e.
C43: Analiza: Analitycy przygotowują z AI brakujące scenariusze na bazie obecnego systemu i dokumentacji - obecnie testy są głównie manualne i słabo sformalizowane. Development: Developerzy wiedzą co dokładnie ma być zaimplementowane - dostają scenariusze z przykładowymi danymi. Review: Reviewerzy sprawdzają czy implementacja pokrywa wszystkie scenariusze. Testing: QA ma gotowe scenariusze e2e w pseudokodzie, które można automatycznie wykonywać. Usprawniamy pozyskiwanie danych testowych i deterministyczny reset scenariuszy. | D43: Opis
D44: Przekazanie knowhow | F44: knowhow | G44: 0
D45: Przygotowanie i wdrożenie brakujących scenariuszy e2e | F45: AI SDLC | G45: 0
D46: Review prac po stronie | F46: AI SDLC | G46: 0
D47: Suma IK.7 | G47: NIE DOSTĘPNE | H47: =SUM(G44:G46)
A49: EK.1 | B49: EK (External Knowledge) | C49: EK.1 - Instrukcje AI dla pracy ze źródłami regulatorów: KNF / UE | D49: Sekcja | I49: Analityk: AI rozbudowuje wymagania regulacyjne, generuje pytania doprecyzowujące, weryfikuje analizę vs źródła.
...

Sheet Capital Markets
A1: AI SDLC z przekazaniem Know-How
A2: BU: | B2: Capital Markets
A4: Kod | B4: Obszar | C4: Tytul / opis | D4: Pozycja kosztowa | F4: Typ do podsumowania | G4: Cena netto [PLN] | H4: Suma | I4: Value proposition
A6: IK.1 | B6: IK (Internal Knowledge) | C6: IK.1 - Skonsolidowana dokumentacja funkcji systemu (aktualnych wersji) dla AI | D6: Sekcja | I6: Analityk: pewność że AI rozumie aktualny stan systemu. Developer: AI i agenci wiedzą co jest już zaimplementowane. Reviewer: kontekst do oceny impaktu. QA: pełny kontekst systemu.
C7: Analiza: Analitycy zyskują pewność, że AI rozumie aktualny stan systemu i impakt na istniejącą funkcjonalność. Skraca to czas weryfikacji pomysłów i redukuje błędy wynikające z nieaktualnej wiedzy. Development: Developerzy i agenci wiedzą co jest już zaimplementowane i AI pomoże im to odszukać. Review: Reviewerzy mają kontekst do oceny czy zmiana nie koliduje z istniejącą funkcjonalnością, jaki jest impakt przed implementacją, czy implementacja została zrealizowana. Testing: QA rozumie pełny kontekst systemu i wie co należy przetestować po zmianach proponowanych w analizie. | D7: Opis
D8: Przekazanie knowhow | F8: knowhow | G8: 1250
D9: Wykonanie skonsolidowanej dokumentacji funkcji systemu (jednej wersji) dla AI | F9: AI SDLC | G9: 7500
D10: Review prac po stronie | F10: AI SDLC | G10: 500
D11: Suma IK.1 | H11: =SUM(G8:G10)
A13: IK.2 | B13: IK (Internal Knowledge) | C13: IK.2 - Baza wiedzy mapująca funkcjonalność na kod / architekturę (funkcjonalność -> UI -> Beans -> baza danych) | D13: Sekcja | I13: Analityk: AI wskazuje miejsca zmian po opisie. Developer: wie dokładnie gdzie zmieniać kod. Reviewer: ocenia pełen impact. QA: wie co testować.
C14: Analiza: Po napisaniu opisu zmian AI wskazuje potencjalne miejsca zmian w kodzie i dokumentacji, a analityk robi finalną walidację. Automatyczne mapowanie nazewnictwa PL (analiza) vs EN (kod) ogranicza błędy wynikające z dwóch języków. Development: Developerzy wiedzą dokładnie gdzie i jak zmieniać kod. Review: Reviewerzy mogą ocenić pełen impact zmiany na kod i architekturę. Testing: Testerzy wiedzą co musi być przetestowane po zmianie. | D14: Opis
D15: Przekazanie knowhow | F15: knowhow | G15: 1250
D16: Wykonanie bazy wiedzy mapującej funkcjonalność na kod i architekturę | F16: AI SDLC | G16: 3750
D17: Review prac po stronie | F17: AI SDLC | G17: 500
D18: Suma IK.2 | H18: =SUM(G15:G17)
A20: IK.3 | B20: IK (Internal Knowledge) | C20: IK.3 - Heurystyczne szacowanie pracochłonności (w oparciu o wartości eksperckie) | D20: Sekcja | I20: Liderzy: estymaty oparte na wartościach eksperckich.
C21: opcja A. (zalecana) szacowanie z wartościami eksperckimi opcja B. (odradzamy) liczenie metryk na bazie kodu/jira jeśli nie istnieją Analiza: Porównujemy artefakty analityczne z realnym stanem systemu, by estymować postęp i złożoność zmian. Liderzy projektu zyskują estymaty oparte na wartościach eksperckich. | D21: Opis
D22: Przekazanie knowhow | F22: knowhow | G22: 0
D23: Przygotowanie heurystycznego szacowania pracochłonności | F23: AI SDLC | G23: 0
D24: Review prac po stronie | F24: AI SDLC | G24: 0
D25: Suma IK.3 | H25: =SUM(G22:G24)
A27: IK.4 | B27: IK (Internal Knowledge) | C27: IK.4 - Skonsolidowana dokumentacja architektury frontendu optymalna dla AI | D27: Sekcja | I27: Analityk: szybsza ocena impaktu na frontend. Developer: AI generuje kod zgodny z architekturą. Reviewer: zgodność z zasadami. QA: spójne testy UI.
C28: Analiza: Ocena impakty zmian na frontendzie. Development: AI generuje kod zgodny z lokalną architekturą i wzorcami. AI i developerzy mają jasne wzorce jak pisać frontend - formularze, tabelki, nazewnictwo, elementy common. Dodatkowe instrukcja uświadamiające AI odnośnie hacków primefaces. Review: Reviewerzy sprawdzają zgodność z zasadami architektonicznymi frontendu. Testing: UI testy e2e są spójne i zgodne z wzorcami. | D28: Opis
D29: Przekazanie knowhow | F29: knowhow | G29: 1250
D30: Wykonanie skonsolidowanej dokumentacji architektury frontendu dla AI | F30: AI SDLC | G30: 1250
D31: Review prac po stronie | F31: AI SDLC | G31: 1250
D32: Suma IK.4 | H32: =SUM(G29:G31)
A34: IK.5 | B34: IK (Internal Knowledge) | C34: IK.5 - Skonsolidowana dokumentacja architektury backendu optymalna dla AI | D34: Sekcja | I34: Analityk: szybsza ocena impaktu na backend. Developer: AI generuje kod zgodny z wzorcami backendu. Reviewer: zgodność architektoniczna. QA: testy zgodne ze wzorcami.
C35: Analiza: Ocena impakty zmian na backendzie. Development: AI generuje kod zgodny z lokalną architekturą i wzorcami. AI i developerzy mają jasne wzorce jak pisać backend - Beana, encje, procedury składowane i exception handling. Review: Reviewerzy sprawdzają zgodność z zasadami architektonicznymi backendu. Testing: Testy backendowe są spójne z przyjętymi wzorcami. AI rozumie strukturę i może pisać testy jednostkowe i integracyjne zgodne z wzorcami. | D35: Opis
D36: Przekazanie knowhow | F36: knowhow | G36: 1250
D37: Wykonanie skonsolidowanej dokumentacji architektury backendu dla AI | F37: AI SDLC | G37: 1250
D38: Review prac po stronie | F38: AI SDLC | G38: 1250
D39: Suma IK.5 | H39: =SUM(G36:G38)
A41: IK.7 | B41: IK (Internal Knowledge) | C41: IK.7 - Implementacja obecnie brakujących scenariuszy e2e (pracochłonne dla wszystkich) | D41: Sekcja | I41: Analityk: brakujące scenariusze z AI. Developer: scenariusze z danymi. Reviewer: sprawdza pokrycie. QA: gotowe e2e.
C42: Analiza: Analitycy przygotowują z AI brakujące scenariusze na bazie obecnego systemu i dokumentacji - obecnie testy są głównie manualne i słabo sformalizowane. Development: Developerzy wiedzą co dokładnie ma być zaimplementowane - dostają scenariusze z przykładowymi danymi. Review: Reviewerzy sprawdzają czy implementacja pokrywa wszystkie scenariusze. Testing: QA ma gotowe scenariusze e2e w pseudokodzie, które można automatycznie wykonywać. Usprawniamy pozyskiwanie danych testowych i deterministyczny reset scenariuszy. | D42: Opis
D43: Przekazanie knowhow | F43: knowhow | G43: 0
D44: Przygotowanie i wdrożenie brakujących scenariuszy e2e | F44: AI SDLC | G44: 0
D45: Review prac po stronie | F45: AI SDLC | G45: 0
D46: Suma IK.7 | G46: NIE DOSTĘPNE | H46: =SUM(G43:G45)
A48: EK.1 | B48: EK (External Knowledge) | C48: EK.1 - Instrukcje AI dla pracy ze źródłami regulatorów: KNF / GPW | D48: Sekcja | I48: Analityk: AI rozbudowuje wymagania regulacyjne KNF/GPW, generuje pytania, weryfikuje analizę.
...

Sheet Refactor Capital Markets
A1: Technologiczna restrukturyzacja
A2: BU: | B2: Capital Markets
A4: Kod | B4: Obszar | C4: Tytul / opis | D4: Pozycja kosztowa | F4: Typ do podsumowania | G4: Cena netto [PLN] | H4: Suma | I4: Value proposition
A5: REF.RE.1 | B5: Rekomendacje | C5: REF.RE.1 - Plan migracji technologicznej + wycena etapowa | D5: Sekcja | I5: Klient: realny plan migracji z etapami i wyceną zamiast estymacji w ciemno.
C6: Wspolne budowanie roadmapy migracji (etapy, ryzyka, zaleznosci) z szablonem estymacji etapowej. Klient dostaje realny plan i kosztorys zamiast estymacji w ciemno. Wsad: IK.7, REF.8, TL.K2.1. Wymagania: inwentarz modulow i zaleznosci oraz wstepne dane o uzyciu funkcjonalnosci, udzial lidera technicznego i wlascicieli kluczowych obszarow systemu. Forma: warsztat roadmapy + iteracyjne doprecyzowanie etapow, ryzyk i zaleznosci oraz wspolne review estymacji etapowej po kazdej iteracji. | D6: Opis
D7: Przekazanie narzedzi | F7: narzedzia | G7: 0
D8: Przekazanie knowhow | F8: knowhow | G8: 0
D9: Warsztat roadmapy migracji i przygotowanie wyceny etapowej | F9: Refactor | G9: 2500
D10: Review prac po stronie | F10: Refactor | G10: 0
D11: Suma REF.RE.1 | H11: =SUM(G7:G10)
A14: REF.1 | B14: CI/CD i build | C14: REF.1 - Standaryzacja CI/CD na Jenkinsfile | D14: Sekcja | I14: Developer + AI: jeden znajomy flow CI/CD dla wszystkich repozytoriów.
C15: Wzorcowy Jenkinsfile (build / test / scan / package / deploy) + biblioteka shared steps. Rollout na kluczowe repo, zeby zespol i agenty AI mialy jeden znajomy flow. Wymagania: dostep do repozytoriow i aktualnych pipelineow Jenkins. Forma: pair programming na 1 wzorcowym pipeline, potem rollout na kolejne kluczowe repozytoria. | D15: Opis
D16: Przekazanie narzedzi | F16: narzedzia | G16: 0
D17: Przekazanie knowhow | F17: knowhow | G17: 1000
D18: Wykonanie wzorcowego Jenkinsfile i shared steps dla pilota | F18: Refactor | G18: 5000
D19: Review prac po stronie | F19: Refactor | G19: 0
D20: Suma REF.1 | H20: =SUM(G16:G19)
A22: REF.2 | B22: CI/CD i build | C22: REF.2 - Uporzadkowanie builda Ant -> Maven/Gradle (dla kluczowych modulow) | D22: Sekcja | I22: Developer: szybsze buildy, dependency management, security scanning.
C23: Konwersja heterogenicznego buildu na standardowy: szybsze buildy, latwiejsze utrzymanie, dzialaja dependency-management i security scanning out-of-the-box. Wymagania: wskazany modul pilotazowy oparty o Ant, dzialajace srodowisko buildowe i testowe dla pilota, TL.K2.8. Forma: praca wlasna na pilocie, knowledge transfer pair programming, review po stronie i rollout po walidacji wzorca. | D23: Opis
D24: Przekazanie narzedzi | F24: narzedzia | G24: 2500
D25: Przekazanie knowhow | F25: knowhow | G25: 0
D26: Migracja builda Ant -> Maven/Gradle dla modulu pilotazowego | F26: Refactor | G26: 15000
D27: Review prac po stronie | F27: Refactor | G27: 1000
D28: Suma REF.2 | H28: =SUM(G24:G27)
A30: REF.3 | B30: Deploy i release | C30: REF.3 - Automatyzacja deploy QA + eliminacja waskiego gardla | D30: Sekcja | I30: Developer: self-service deploy, rollback. Koniec wąskiego gardła.
C31: Self-service deploy na QA z pipelineu (jeden klik + API dla agenta), rollback, runbook. Eliminacja waskiego gardla tylko X potrafi wgrac release. Wymagania: dostep do srodowiska QA oraz uprawnienia do deploy/rollback, uzgodniony runbook procesu release. Forma: pair programming na 1 aplikacji / module, praca wlasna gdy wymagana, standaryzacja i rollout dla kolejnych aplikacji / modulow. | D31: Opis
D32: Przekazanie narzedzi | F32: narzedzia | G32: 0
D33: Przekazanie knowhow | F33: knowhow | G33: 0
D34: Automatyzacja deploy QA i rollback dla pilota | F34: Refactor | G34: 2500
D35: Review prac po stronie | F35: Refactor | G35: 0
D36: Suma REF.3 | H36: =SUM(G32:G35)
A38: REF.4 | B38: Deploy i release | C38: REF.4 - Ujednolicenie zarzadzania artefaktami release | D38: Sekcja | I38: Tech lead: w każdej chwili wiadomo co i kiedy trafiło na środowisko.
C39: Nexus / Artifactory (lub spojny katalog z wersjonowaniem i retention). W kazdej chwili wiadomo co i kiedy trafilo na srodowisko / do klienta. Zaleznosc: REF.1. Wymagania: decyzja o docelowym repo artefaktow oraz uzgodniona polityka wersjonowania i retencji. Forma: wdrozenie polityki artefaktow dla pilota i rozszerzenie standardu na wszystkie releasey. | D39: Opis
D40: Przekazanie narzedzi | F40: narzedzia
D41: Przekazanie knowhow | F41: knowhow | G41: 500
D42: Ujednolicenie repo artefaktow i polityki wersjonowania | F42: Refactor | G42: 2000
D43: Review prac po stronie | F43: Refactor | G43: 0
D44: Suma REF.4 | H44: =SUM(G40:G43)
A46: REF.5 | B46: Deploy i release | C46: REF.5 - Automatyzacja iOS build/release (dedykowany Mac worker + Fastlane) | D46: Sekcja | I46: iOS developer: build i podpisywanie w pipeline. Koniec ręcznych obejść.
C47: Mac jako Jenkins agent, certyfikaty/profile przez Fastlane, build i podpisywanie w pipeline. Koniec recznych obejsc z kontami i uprawnieniami. Wymagania: sprzet Mac oraz konto Apple Developer. Forma: konfiguracja Mac workera + Fastlane na jednym pipeline iOS, knowledge transfer pair programming, walidacja podpisywania i publikacji, nastepnie rollout. | D47: Opis
...

Sheet Narzędzia
A1: Narzędzia AI SDLC z przekazaniem Know-How
A4: Kod | B4: Obszar | C4: Tytul / opis | D4: Pozycja kosztowa | F4: Typ do podsumowania | G4: Cena netto [PLN] | H4: Suma | I4: Value proposition
A5: RE.1 | B5: Know-how i rekomendacje | C5: RE.1 - Rekomendacje odnośnie narzędzi AI (korzystających z dostępnych subskrypcji Github Copilot, Codex, Copilot 360), z uwzględnieniem pracy człowieka z AI oraz integracji AI z CI. | D5: Sekcja | I5: Rekomendacje narzędzi AI dopasowane do istniejących subskrypcji i infrastruktury.
D6: Przekazanie Rekomendacji | F6: knowhow | G6: 2500
A7: IK.1 | B7: IK (Internal Knowledge) | C7: IK.1 - Skonsolidowana dokumentacja funkcji systemu (aktualnych wersji) dla AI | D7: Sekcja | I7: Narzędzie do konsolidacji dokumentacji funkcji systemu dla AI.
D8: Przekazanie narzedzi | F8: narzedzia | G8: 750
A9: IK.2 | B9: IK (Internal Knowledge) | C9: IK.2 - Baza wiedzy mapująca funkcjonalność na kod / architekturę (funkcjonalność -> UI -> Beans -> baza danych) | D9: Sekcja | I9: Narzędzie mapowania funkcjonalności na kod i architekturę.
D10: Przekazanie narzedzi | F10: narzedzia | G10: 750
A11: IK.3 | B11: IK (Internal Knowledge) | C11: IK.3 - Heurystyczne szacowanie pracochłonności (w oparciu o wartości eksperckie) | D11: Sekcja | I11: Narzędzie heurystycznego szacowania pracochłonności.
D12: Przekazanie narzedzi | F12: narzedzia | G12: 300
A13: IK.4 | B13: IK (Internal Knowledge) | C13: IK.4 - Skonsolidowana dokumentacja architektury frontendu optymalna dla AI | D13: Sekcja | I13: Narzędzie dokumentacji architektury frontendu dla AI.
D14: Przekazanie narzedzi | F14: narzedzia | G14: 1250
A15: IK.5 | B15: IK (Internal Knowledge) | C15: IK.5 - Skonsolidowana dokumentacja architektury backendu optymalna dla AI | D15: Sekcja | I15: Narzędzie dokumentacji architektury backendu dla AI.
D16: Przekazanie narzedzi | F16: narzedzia | G16: 1250
A17: IK.7 | B17: IK (Internal Knowledge) | C17: IK.7 - Implementacja obecnie brakujących scenariuszy e2e (pracochłonne dla wszystkich) | D17: Sekcja | I17: Narzędzie implementacji scenariuszy e2e.
D18: Przekazanie narzedzi | F18: narzedzia | G18: 0
A19: EK.1 | B19: EK (External Knowledge) | C19: EK.1 - Instrukcje AI dla pracy ze źródłami regulatorów: KNF / UE | D19: Sekcja | I19: Narzędzie AI do pracy ze źródłami regulatorów KNF/UE.
D20: Przekazanie narzedzi | F20: narzedzia | G20: 0
A21: TL.1 | B21: Analiza | C21: TL.1 - Przygotowanie narzędzi dla AI dedykowanych dla Analityków (UI z dostępem do baz wiedzy i tooli, podobnie jak dla developerów) | D21: Sekcja | I21: Środowisko AI dla analityków.
D22: Przekazanie narzedzi | F22: narzedzia | G22: 2500
A23: TL.2 | B23: Analiza | C23: TL.2 - Instrukcje AI do Review Analizy (Gap analysis / Spike Analysis, brakujące elementy, zasady jakościowe, definition of ready) | D23: Sekcja | I23: Instrukcje AI do gap analysis i spike analysis.
D24: Przekazanie narzedzi | F24: narzedzia | G24: 1250
A25: TL.2.1 | B25: Analiza | C25: TL.2.1 - Instrukcje AI do Review Analizy vs. źródłami regulatorów: KNF / UE (przyśpiesza, nie zwalnia analityka z odpowiedzialności) | D25: Sekcja | I25: Instrukcje AI do review analizy vs KNF/UE.
D26: Przekazanie narzedzi | F26: narzedzia | G26: 0
A27: TL.3 | B27: Analiza | C27: TL.3 - Instrukcje AI do generowania wstępnych diagramów BPMN / UML (edytowalnych, bez integracji z Enterprise Architect) | D27: Sekcja | I27: Generowanie diagramów BPMN/UML z AI.
D28: Przekazanie narzedzi | F28: narzedzia | G28: 1000
A29: TL.4 | B29: Analiza | C29: TL.4 - Instrukcje/narzędzia dla AI do generowania wstępnego (low fidelity) UI / UX. (bez integracji z Enterprise Architect) | D29: Sekcja | I29: Generowanie UI/UX low fidelity z AI.
D30: Przekazanie narzedzi | F30: narzedzia | G30: 1250
A31: TL.5 | B31: Analiza | C31: TL.5 - Instrukcja dla AI proponowania scenariuszy w oparciu o analizę (ui, validacje, reguły, przykłady danych) (forma dla człowieka) | D31: Sekcja | I31: AI proponuje scenariusze testowe z analizy.
D32: Przekazanie narzedzi | F32: narzedzia | G32: 1250
A33: TL.29 | B33: Analiza | C33: TL.29 - Integracja z Enterprise Architect (XMI export lub baza sqlserver lub Sparx Pro Cloud Service) | D33: Sekcja | I33: Integracja z Enterprise Architect.
D34: Przekazanie narzedzi | F34: narzedzia | G34: 2000
A35: TL.30 | B35: Analiza | C35: TL.30 - Sformułowanie zmian w Projekcie (dokumentacja analityczna) w speckę dla AI | D35: Sekcja | I35: Formatowanie specyfikacji dla AI.
D36: Przekazanie narzedzi | F36: narzedzia
A37: TL.6 [Development] | B37: Development | C37: TL.6 [Development] - Reverse Engineering mapowania funkcjonalność na kod / architekturę (funkcjonalność -> UI -> Beans -> baza danych) | D37: Sekcja
D38: Przekazanie narzedzi | F38: narzedzia | G38: 1800
A39: TL.9 | B39: Development | C39: TL.9 - Integracja AI z bazą oracle (readonly), analiza modelu, odpytywanie o przykładowe dane (dowolne dopuszczone środowisko np: testowe) | D39: Sekcja | I39: AI odpyta bazę Oracle (readonly).
D40: Przekazanie narzedzi | F40: narzedzia | G40: 800
A41: TL.10 | B41: Development | C41: TL.10 - Reverse Engineering zasad architektonicznych | D41: Sekcja | I41: Reverse engineering zasad architektonicznych.
D42: Przekazanie narzedzi | F42: narzedzia | G42: 1800
...
